Workbook
Name SegmentaçãodeDados_Fatores: #REF!
Name SlicerCache_Table_1_Col_1: #N/A

Sheet DRE 
B1: Selecione o último mês nos quais o dados são realizados e não projetados: | K1: DRE
AV2: Bossa Nova Investimentos
B3: Realizado | K3: Projetado
B4: 45292 | C4: =DATE(YEAR(B4),MONTH(B4)+1,DAY(B4)) -> 45323 | D4: =DATE(YEAR(C4),MONTH(C4)+1,DAY(C4)) -> 45352 | E4: =DATE(YEAR(D4),MONTH(D4)+1,DAY(D4)) -> 45383 | F4: =DATE(YEAR(E4),MONTH(E4)+1,DAY(E4)) -> 45413 | G4: =DATE(YEAR(F4),MONTH(F4)+1,DAY(F4)) -> 45444 | H4: =DATE(YEAR(G4),MONTH(G4)+1,DAY(G4)) -> 45474 | I4: =DATE(YEAR(H4),MONTH(H4)+1,DAY(H4)) -> 45505 | J4: =DATE(YEAR(I4),MONTH(I4)+1,DAY(I4)) -> 45536 | ... AW4: =DATE(YEAR(AV4),MONTH(AV4)+1,DAY(AV4)) -> 46722
A5: Total de Clientes | B5: 0 | C5: 0 | D5: 0 | E5: 0 | F5: 0 | G5: 0 | H5: 0 | I5: 0 | J5: 0 | K5: 0 | L5: 0 | M5: 0 | N5: 0 | O5: 0 | P5: 0 | Q5: 0 | R5: 0 | S5: 0 | T5: 0 | U5: 0 | V5: 0 | W5: 0 | X5: 0 | Y5: 0 | Z5: 0 | AA5: 0 | AB5: 0 | AC5: 0 | AD5: 0 | AE5: 0 | AF5: 0 | AG5: 0 | AH5: 0 | AI5: 0 | AJ5: 0 | AK5: 0 | AL5: 0 | AM5: 0 | AN5: 0 | AO5: 0 | AP5: 0 | AQ5: 0 | AR5: 0 | AS5: 0 | AT5: 0 | AU5: 0 | AV5: 0 | AW5: 0
A6: Novos Clientes | B6: 0 | C6: 0 | D6: 0 | E6: 0 | F6: 0 | G6: 0 | H6: 0 | I6: 0 | J6: 0 | K6: 0 | L6: 0 | M6: 0 | N6: 0 | O6: 0 | P6: 0 | Q6: 0 | R6: 0 | S6: 0 | T6: 0 | U6: 0 | V6: 0 | W6: 0 | X6: 0 | Y6: 0 | Z6: 0 | AA6: 0 | AB6: 0 | AC6: 0 | AD6: 0 | AE6: 0 | AF6: 0 | AG6: 0 | AH6: 0 | AI6: 0 | AJ6: 0 | AK6: 0 | AL6: 0 | AM6: 0 | AN6: 0 | AO6: 0 | AP6: 0 | AQ6: 0 | AR6: 0 | AS6: 0 | AT6: 0 | AU6: 0 | AV6: 0 | AW6: 0
A7: Clientes Perdidos | B7: 0 | C7: 0 | D7: 0 | E7: 0 | F7: 0 | G7: 0 | H7: 0 | I7: 0 | J7: 0 | K7: 0 | L7: 0 | M7: 0 | N7: 0 | O7: 0 | P7: 0 | Q7: 0 | R7: 0 | S7: 0 | T7: 0 | U7: 0 | V7: 0 | W7: 0 | X7: 0 | Y7: 0 | Z7: 0 | AA7: 0 | AB7: 0 | AC7: 0 | AD7: 0 | AE7: 0 | AF7: 0 | AG7: 0 | AH7: 0 | AI7: 0 | AJ7: 0 | AK7: 0 | AL7: 0 | AM7: 0 | AN7: 0 | AO7: 0 | AP7: 0 | AQ7: 0 | AR7: 0 | AS7: 0 | AT7: 0 | AU7: 0 | AV7: 0 | AW7: 0
A8: Churn | B8: =IF(B5=0,0,B7/B5) -> 0 | C8: =IF(C5=0,0,C7/C5) -> 0 | D8: =IF(D5=0,0,D7/D5) -> 0 | E8: =IF(E5=0,0,E7/E5) -> 0 | F8: =IF(F5=0,0,F7/F5) -> 0 | G8: =IF(G5=0,0,G7/G5) -> 0 | H8: =IF(H5=0,0,H7/H5) -> 0 | I8: =IF(I5=0,0,I7/I5) -> 0 | ... AW8: =IF(AW5=0,0,AW7/AW5) -> 0
A10: Receita Recorrente | B10: 0 | C10: 0 | D10: 0 | E10: 0 | F10: 0 | G10: 0 | H10: 0 | I10: 0 | J10: 0 | K10: 0 | L10: 0 | M10: 0 | N10: 0 | O10: 0 | P10: 0 | Q10: 0 | R10: 0 | S10: 0 | T10: 0 | U10: 0 | V10: 0 | W10: 0 | X10: 0 | Y10: 0 | Z10: 0 | AA10: 0 | AB10: 0 | AC10: 0 | AD10: 0 | AE10: 0 | AF10: 0 | AG10: 0 | AH10: 0 | AI10: 0 | AJ10: 0 | AK10: 0 | AL10: 0 | AM10: 0 | AN10: 0 | AO10: 0 | AP10: 0 | AQ10: 0 | AR10: 0 | AS10: 0 | AT10: 0 | AU10: 0 | AV10: 0 | AW10: 0
A11: Receita Não Recorrente | B11: 0 | C11: 0 | D11: 0 | E11: 0 | F11: 0 | G11: 0 | H11: 0 | I11: 0 | J11: 0 | K11: 0 | L11: 0 | M11: 0 | N11: 0 | O11: 0 | P11: 0 | Q11: 0 | R11: 0 | S11: 0 | T11: 0 | U11: 0 | V11: 0 | W11: 0 | X11: 0 | Y11: 0 | Z11: 0 | AA11: 0 | AB11: 0 | AC11: 0 | AD11: 0 | AE11: 0 | AF11: 0 | AG11: 0 | AH11: 0 | AI11: 0 | AJ11: 0 | AK11: 0 | AL11: 0 | AM11: 0 | AN11: 0 | AO11: 0 | AP11: 0 | AQ11: 0 | AR11: 0 | AS11: 0 | AT11: 0 | AU11: 0 | AV11: 0 | AW11: 0
A12: Receita Bruta | B12: =SUM(B9:B11) -> 0 | C12: =SUM(C9:C11) -> 0 | D12: =SUM(D9:D11) -> 0 | E12: =SUM(E9:E11) -> 0 | F12: =SUM(F9:F11) -> 0 | G12: =SUM(G9:G11) -> 0 | H12: =SUM(H9:H11) -> 0 | I12: =SUM(I9:I11) -> 0 | ... AW12: =SUM(AW9:AW11) -> 0
A13: Taxa de Crescimento | C13: =IFERROR(C12/B12-1,0) -> 0 | D13: =IFERROR(D12/C12-1,0) -> 0 | E13: =IFERROR(E12/D12-1,0) -> 0 | F13: =IFERROR(F12/E12-1,0) -> 0 | G13: =IFERROR(G12/F12-1,0) -> 0 | H13: =IFERROR(H12/G12-1,0) -> 0 | I13: =IFERROR(I12/H12-1,0) -> 0 | J13: =IFERROR(J12/I12-1,0) -> 0 | ... AW13: =IFERROR(AW12/AV12-1,0) -> 0
A15: (-) Impostos | B15: 0 | C15: 0 | D15: 0 | E15: 0 | F15: 0 | G15: 0 | H15: 0 | I15: 0 | J15: 0 | K15: 0 | L15: 0 | M15: 0 | N15: 0 | O15: 0 | P15: 0 | Q15: 0 | R15: 0 | S15: 0 | T15: 0 | U15: 0 | V15: 0 | W15: 0 | X15: 0 | Y15: 0 | Z15: 0 | AA15: 0 | AB15: 0 | AC15: 0 | AD15: 0 | AE15: 0 | AF15: 0 | AG15: 0 | AH15: 0 | AI15: 0 | AJ15: 0 | AK15: 0 | AL15: 0 | AM15: 0 | AN15: 0 | AO15: 0 | AP15: 0 | AQ15: 0 | AR15: 0 | AS15: 0 | AT15: 0 | AU15: 0 | AV15: 0 | AW15: 0
A16: (-) Deduções | B16: 0 | C16: 0 | D16: 0 | E16: 0 | F16: 0 | G16: 0 | H16: 0 | I16: 0 | J16: 0 | K16: 0 | L16: 0 | M16: 0 | N16: 0 | O16: 0 | P16: 0 | Q16: 0 | R16: 0 | S16: 0 | T16: 0 | U16: 0 | V16: 0 | W16: 0 | X16: 0 | Y16: 0 | Z16: 0 | AA16: 0 | AB16: 0 | AC16: 0 | AD16: 0 | AE16: 0 | AF16: 0 | AG16: 0 | AH16: 0 | AI16: 0 | AJ16: 0 | AK16: 0 | AL16: 0 | AM16: 0 | AN16: 0 | AO16: 0 | AP16: 0 | AQ16: 0 | AR16: 0 | AS16: 0 | AT16: 0 | AU16: 0 | AV16: 0 | AW16: 0
A17: Receita Liquida | B17: =B12-B16-B15 -> 0 | C17: =C12-C16-C15 -> 0 | D17: =D12-D16-D15 -> 0 | E17: =E12-E16-E15 -> 0 | F17: =F12-F16-F15 -> 0 | G17: =G12-G16-G15 -> 0 | H17: =H12-H16-H15 -> 0 | I17: =I12-I16-I15 -> 0 | ... AW17: =AW12-AW16-AW15 -> 0
A18: (-) Custo do serviço prestado | B18: 0 | C18: 0 | D18: 0 | E18: 0 | F18: 0 | G18: 0 | H18: 0 | I18: 0 | J18: 0 | K18: 0 | L18: 0 | M18: 0 | N18: 0 | O18: 0 | P18: 0 | Q18: 0 | R18: 0 | S18: 0 | T18: 0 | U18: 0 | V18: 0 | W18: 0 | X18: 0 | Y18: 0 | Z18: 0 | AA18: 0 | AB18: 0 | AC18: 0 | AD18: 0 | AE18: 0 | AF18: 0 | AG18: 0 | AH18: 0 | AI18: 0 | AJ18: 0 | AK18: 0 | AL18: 0 | AM18: 0 | AN18: 0 | AO18: 0 | AP18: 0 | AQ18: 0 | AR18: 0 | AS18: 0 | AT18: 0 | AU18: 0 | AV18: 0 | AW18: 0
A19: Lucro Bruto | B19: =B17-B18 -> 0 | C19: =C17-C18 -> 0 | D19: =D17-D18 -> 0 | E19: =E17-E18 -> 0 | F19: =F17-F18 -> 0 | G19: =G17-G18 -> 0 | H19: =H17-H18 -> 0 | I19: =I17-I18 -> 0 | ... AW19: =AW17-AW18 -> 0
A20: Margem Bruta | B20: =IFERROR(B19/B$12,0) -> 0 | C20: =IFERROR(C19/C$12,0) -> 0 | D20: =IFERROR(D19/D$12,0) -> 0 | E20: =IFERROR(E19/E$12,0) -> 0 | F20: =IFERROR(F19/F$12,0) -> 0 | G20: =IFERROR(G19/G$12,0) -> 0 | H20: =IFERROR(H19/H$12,0) -> 0 | I20: =IFERROR(I19/I$12,0) -> 0 | ... AW20: =IFERROR(AW19/AW$12,0) -> 0
A22: DESPESAS E CUSTOS | B22: =B23+B28+B33+B38 -> 0 | C22: =C23+C28+C33+C38 -> 0 | D22: =D23+D28+D33+D38 -> 0 | E22: =E23+E28+E33+E38 -> 0 | F22: =F23+F28+F33+F38 -> 0 | G22: =G23+G28+G33+G38 -> 0 | H22: =H23+H28+H33+H38 -> 0 | I22: =I23+I28+I33+I38 -> 0 | ... AW22: =AW23+AW28+AW33+AW38 -> 0
A23: Custos com TI | B23: =B25+B26 -> 0 | C23: =C25+C26 -> 0 | D23: =D25+D26 -> 0 | E23: =E25+E26 -> 0 | F23: =F25+F26 -> 0 | G23: =G25+G26 -> 0 | H23: =H25+H26 -> 0 | I23: =I25+I26 -> 0 | ... AW23: =AW25+AW26 -> 0
A24: Head Count | B24: 0 | C24: 0 | D24: 0 | E24: 0 | F24: 0 | G24: 0 | H24: 0 | I24: 0 | J24: 0 | K24: 0 | L24: 0 | M24: 0 | N24: 0 | O24: 0 | P24: 0 | Q24: 0 | R24: 0 | S24: 0 | T24: 0 | U24: 0 | V24: 0 | W24: 0 | X24: 0 | Y24: 0 | Z24: 0 | AA24: 0 | AB24: 0 | AC24: 0 | AD24: 0 | AE24: 0 | AF24: 0 | AG24: 0 | AH24: 0 | AI24: 0 | AJ24: 0 | AK24: 0 | AL24: 0 | AM24: 0 | AN24: 0 | AO24: 0 | AP24: 0 | AQ24: 0 | AR24: 0 | AS24: 0 | AT24: 0 | AU24: 0 | AV24: 0 | AW24: 0
A25: Pessoal | B25: 0 | C25: 0 | D25: 0 | E25: 0 | F25: 0 | G25: 0 | H25: 0 | I25: 0 | J25: 0 | K25: 0 | L25: 0 | M25: 0 | N25: 0 | O25: 0 | P25: 0 | Q25: 0 | R25: 0 | S25: 0 | T25: 0 | U25: 0 | V25: 0 | W25: 0 | X25: 0 | Y25: 0 | Z25: 0 | AA25: 0 | AB25: 0 | AC25: 0 | AD25: 0 | AE25: 0 | AF25: 0 | AG25: 0 | AH25: 0 | AI25: 0 | AJ25: 0 | AK25: 0 | AL25: 0 | AM25: 0 | AN25: 0 | AO25: 0 | AP25: 0 | AQ25: 0 | AR25: 0 | AS25: 0 | AT25: 0 | AU25: 0 | AV25: 0 | AW25: 0
A26: Softwares | B26: 0 | C26: 0 | D26: 0 | E26: 0 | F26: 0 | G26: 0 | H26: 0 | I26: 0 | J26: 0 | K26: 0 | L26: 0 | M26: 0 | N26: 0 | O26: 0 | P26: 0 | Q26: 0 | R26: 0 | S26: 0 | T26: 0 | U26: 0 | V26: 0 | W26: 0 | X26: 0 | Y26: 0 | Z26: 0 | AA26: 0 | AB26: 0 | AC26: 0 | AD26: 0 | AE26: 0 | AF26: 0 | AG26: 0 | AH26: 0 | AI26: 0 | AJ26: 0 | AK26: 0 | AL26: 0 | AM26: 0 | AN26: 0 | AO26: 0 | AP26: 0 | AQ26: 0 | AR26: 0 | AS26: 0 | AT26: 0 | AU26: 0 | AV26: 0 | AW26: 0
A27: Outros | B27: 0 | C27: 0 | D27: 0 | E27: 0 | F27: 0 | G27: 0 | H27: 0 | I27: 0 | J27: 0 | K27: 0 | L27: 0 | M27: 0 | N27: 0 | O27: 0 | P27: 0 | Q27: 0 | R27: 0 | S27: 0 | T27: 0 | U27: 0 | V27: 0 | W27: 0 | X27: 0 | Y27: 0 | Z27: 0 | AA27: 0 | AB27: 0 | AC27: 0 | AD27: 0 | AE27: 0 | AF27: 0 | AG27: 0 | AH27: 0 | AI27: 0 | AJ27: 0 | AK27: 0 | AL27: 0 | AM27: 0 | AN27: 0 | AO27: 0 | AP27: 0 | AQ27: 0 | AR27: 0 | AS27: 0 | AT27: 0 | AU27: 0 | AV27: 0 | AW27: 0
A28: Custos Administrativos | B28: =B30+B31 -> 0 | C28: =C30+C31 -> 0 | D28: =D30+D31 -> 0 | E28: =E30+E31 -> 0 | F28: =F30+F31 -> 0 | G28: =G30+G31 -> 0 | H28: =H30+H31 -> 0 | I28: =I30+I31 -> 0 | ... AW28: =AW30+AW31 -> 0
A29: Head Count | B29: 0 | C29: 0 | D29: 0 | E29: 0 | F29: 0 | G29: 0 | H29: 0 | I29: 0 | J29: 0 | K29: 0 | L29: 0 | M29: 0 | N29: 0 | O29: 0 | P29: 0 | Q29: 0 | R29: 0 | S29: 0 | T29: 0 | U29: 0 | V29: 0 | W29: 0 | X29: 0 | Y29: 0 | Z29: 0 | AA29: 0 | AB29: 0 | AC29: 0 | AD29: 0 | AE29: 0 | AF29: 0 | AG29: 0 | AH29: 0 | AI29: 0 | AJ29: 0 | AK29: 0 | AL29: 0 | AM29: 0 | AN29: 0 | AO29: 0 | AP29: 0 | AQ29: 0 | AR29: 0 | AS29: 0 | AT29: 0 | AU29: 0 | AV29: 0 | AW29: 0
A30: Pessoal | B30: 0 | C30: 0 | D30: 0 | E30: 0 | F30: 0 | G30: 0 | H30: 0 | I30: 0 | J30: 0 | K30: 0 | L30: 0 | M30: 0 | N30: 0 | O30: 0 | P30: 0 | Q30: 0 | R30: 0 | S30: 0 | T30: 0 | U30: 0 | V30: 0 | W30: 0 | X30: 0 | Y30: 0 | Z30: 0 | AA30: 0 | AB30: 0 | AC30: 0 | AD30: 0 | AE30: 0 | AF30: 0 | AG30: 0 | AH30: 0 | AI30: 0 | AJ30: 0 | AK30: 0 | AL30: 0 | AM30: 0 | AN30: 0 | AO30: 0 | AP30: 0 | AQ30: 0 | AR30: 0 | AS30: 0 | AT30: 0 | AU30: 0 | AV30: 0 | AW30: 0
A31: Softwares | B31: 0 | C31: 0 | D31: 0 | E31: 0 | F31: 0 | G31: 0 | H31: 0 | I31: 0 | J31: 0 | K31: 0 | L31: 0 | M31: 0 | N31: 0 | O31: 0 | P31: 0 | Q31: 0 | R31: 0 | S31: 0 | T31: 0 | U31: 0 | V31: 0 | W31: 0 | X31: 0 | Y31: 0 | Z31: 0 | AA31: 0 | AB31: 0 | AC31: 0 | AD31: 0 | AE31: 0 | AF31: 0 | AG31: 0 | AH31: 0 | AI31: 0 | AJ31: 0 | AK31: 0 | AL31: 0 | AM31: 0 | AN31: 0 | AO31: 0 | AP31: 0 | AQ31: 0 | AR31: 0 | AS31: 0 | AT31: 0 | AU31: 0 | AV31: 0 | AW31: 0
A32: Outros | B32: 0 | C32: 0 | D32: 0 | E32: 0 | F32: 0 | G32: 0 | H32: 0 | I32: 0 | J32: 0 | K32: 0 | L32: 0 | M32: 0 | N32: 0 | O32: 0 | P32: 0 | Q32: 0 | R32: 0 | S32: 0 | T32: 0 | U32: 0 | V32: 0 | W32: 0 | X32: 0 | Y32: 0 | Z32: 0 | AA32: 0 | AB32: 0 | AC32: 0 | AD32: 0 | AE32: 0 | AF32: 0 | AG32: 0 | AH32: 0 | AI32: 0 | AJ32: 0 | AK32: 0 | AL32: 0 | AM32: 0 | AN32: 0 | AO32: 0 | AP32: 0 | AQ32: 0 | AR32: 0 | AS32: 0 | AT32: 0 | AU32: 0 | AV32: 0 | AW32: 0
A33: Comercial/Marketing | B33: =B35+B36 -> 0 | C33: =C35+C36 -> 0 | D33: =D35+D36 -> 0 | E33: =E35+E36 -> 0 | F33: =F35+F36 -> 0 | G33: =G35+G36 -> 0 | H33: =H35+H36 -> 0 | I33: =I35+I36 -> 0 | ... AW33: =AW35+AW36 -> 0
A34: Head Count | B34: 0 | C34: 0 | D34: 0 | E34: 0 | F34: 0 | G34: 0 | H34: 0 | I34: 0 | J34: 0 | K34: 0 | L34: 0 | M34: 0 | N34: 0 | O34: 0 | P34: 0 | Q34: 0 | R34: 0 | S34: 0 | T34: 0 | U34: 0 | V34: 0 | W34: 0 | X34: 0 | Y34: 0 | Z34: 0 | AA34: 0 | AB34: 0 | AC34: 0 | AD34: 0 | AE34: 0 | AF34: 0 | AG34: 0 | AH34: 0 | AI34: 0 | AJ34: 0 | AK34: 0 | AL34: 0 | AM34: 0 | AN34: 0 | AO34: 0 | AP34: 0 | AQ34: 0 | AR34: 0 | AS34: 0 | AT34: 0 | AU34: 0 | AV34: 0 | AW34: 0
A35: Pessoal | B35: 0 | C35: 0 | D35: 0 | E35: 0 | F35: 0 | G35: 0 | H35: 0 | I35: 0 | J35: 0 | K35: 0 | L35: 0 | M35: 0 | N35: 0 | O35: 0 | P35: 0 | Q35: 0 | R35: 0 | S35: 0 | T35: 0 | U35: 0 | V35: 0 | W35: 0 | X35: 0 | Y35: 0 | Z35: 0 | AA35: 0 | AB35: 0 | AC35: 0 | AD35: 0 | AE35: 0 | AF35: 0 | AG35: 0 | AH35: 0 | AI35: 0 | AJ35: 0 | AK35: 0 | AL35: 0 | AM35: 0 | AN35: 0 | AO35: 0 | AP35: 0 | AQ35: 0 | AR35: 0 | AS35: 0 | AT35: 0 | AU35: 0 | AV35: 0 | AW35: 0
A36: Softwares | B36: 0 | C36: 0 | D36: 0 | E36: 0 | F36: 0 | G36: 0 | H36: 0 | I36: 0 | J36: 0 | K36: 0 | L36: 0 | M36: 0 | N36: 0 | O36: 0 | P36: 0 | Q36: 0 | R36: 0 | S36: 0 | T36: 0 | U36: 0 | V36: 0 | W36: 0 | X36: 0 | Y36: 0 | Z36: 0 | AA36: 0 | AB36: 0 | AC36: 0 | AD36: 0 | AE36: 0 | AF36: 0 | AG36: 0 | AH36: 0 | AI36: 0 | AJ36: 0 | AK36: 0 | AL36: 0 | AM36: 0 | AN36: 0 | AO36: 0 | AP36: 0 | AQ36: 0 | AR36: 0 | AS36: 0 | AT36: 0 | AU36: 0 | AV36: 0 | AW36: 0
A37: Outros | B37: 0 | C37: 0 | D37: 0 | E37: 0 | F37: 0 | G37: 0 | H37: 0 | I37: 0 | J37: 0 | K37: 0 | L37: 0 | M37: 0 | N37: 0 | O37: 0 | P37: 0 | Q37: 0 | R37: 0 | S37: 0 | T37: 0 | U37: 0 | V37: 0 | W37: 0 | X37: 0 | Y37: 0 | Z37: 0 | AA37: 0 | AB37: 0 | AC37: 0 | AD37: 0 | AE37: 0 | AF37: 0 | AG37: 0 | AH37: 0 | AI37: 0 | AJ37: 0 | AK37: 0 | AL37: 0 | AM37: 0 | AN37: 0 | AO37: 0 | AP37: 0 | AQ37: 0 | AR37: 0 | AS37: 0 | AT37: 0 | AU37: 0 | AV37: 0 | AW37: 0
A38: Outros Resultados Operacionais (+/-) | B38: 0 | C38: 0 | D38: 0 | E38: 0 | F38: 0 | G38: 0 | H38: 0 | I38: 0 | J38: 0 | K38: 0 | L38: 0 | M38: 0 | N38: 0 | O38: 0 | P38: 0 | Q38: 0 | R38: 0 | S38: 0 | T38: 0 | U38: 0 | V38: 0 | W38: 0 | X38: 0 | Y38: 0 | Z38: 0 | AA38: 0 | AB38: 0 | AC38: 0 | AD38: 0 | AE38: 0 | AF38: 0 | AG38: 0 | AH38: 0 | AI38: 0 | AJ38: 0 | AK38: 0 | AL38: 0 | AM38: 0 | AN38: 0 | AO38: 0 | AP38: 0 | AQ38: 0 | AR38: 0 | AS38: 0 | AT38: 0 | AU38: 0 | AV38: 0 | AW38: 0
A39: EBIT | B39: =B19-B22 -> 0 | C39: =C19-C22 -> 0 | D39: =D19-D22 -> 0 | E39: =E19-E22 -> 0 | F39: =F19-F22 -> 0 | G39: =G19-G22 -> 0 | H39: =H19-H22 -> 0 | I39: =I19-I22 -> 0 | ... AW39: =AW19-AW22 -> 0
A40: Margem EBIT | B40: =IFERROR(B39/B12,0) -> 0 | C40: =IFERROR(C39/C12,0) -> 0 | D40: =IFERROR(D39/D12,0) -> 0 | E40: =IFERROR(E39/E12,0) -> 0 | F40: =IFERROR(F39/F12,0) -> 0 | G40: =IFERROR(G39/G12,0) -> 0 | H40: =IFERROR(H39/H12,0) -> 0 | I40: =IFERROR(I39/I12,0) -> 0 | ... AW40: =IFERROR(AW39/AW12,0) -> 0
A42: Resultado Financeiro (+/-) | B42: 0 | C42: 0 | D42: 0 | E42: 0 | F42: 0 | G42: 0 | H42: 0 | I42: 0 | J42: 0 | K42: 0 | L42: 0 | M42: 0 | N42: 0 | O42: 0 | P42: 0 | Q42: 0 | R42: 0 | S42: 0 | T42: 0 | U42: 0 | V42: 0 | W42: 0 | X42: 0 | Y42: 0 | Z42: 0 | AA42: 0 | AB42: 0 | AC42: 0 | AD42: 0 | AE42: 0 | AF42: 0 | AG42: 0 | AH42: 0 | AI42: 0 | AJ42: 0 | AK42: 0 | AL42: 0 | AM42: 0 | AN42: 0 | AO42: 0 | AP42: 0 | AQ42: 0 | AR42: 0 | AS42: 0 | AT42: 0 | AU42: 0 | AV42: 0 | AW42: 0
A43: Imposto Sobre O Lucro | B43: 0 | C43: 0 | D43: 0 | E43: 0 | F43: 0 | G43: 0 | H43: 0 | I43: 0 | J43: 0 | K43: 0 | L43: 0 | M43: 0 | N43: 0 | O43: 0 | P43: 0 | Q43: 0 | R43: 0 | S43: 0 | T43: 0 | U43: 0 | V43: 0 | W43: 0 | X43: 0 | Y43: 0 | Z43: 0 | AA43: 0 | AB43: 0 | AC43: 0 | AD43: 0 | AE43: 0 | AF43: 0 | AG43: 0 | AH43: 0 | AI43: 0 | AJ43: 0 | AK43: 0 | AL43: 0 | AM43: 0 | AN43: 0 | AO43: 0 | AP43: 0 | AQ43: 0 | AR43: 0 | AS43: 0 | AT43: 0 | AU43: 0 | AV43: 0 | AW43: 0
A44: Lucro Líquido | B44: =B39+B42-B43 -> 0 | C44: =C39+C42-C43 -> 0 | D44: =D39+D42-D43 -> 0 | E44: =E39+E42-E43 -> 0 | F44: =F39+F42-F43 -> 0 | G44: =G39+G42-G43 -> 0 | H44: =H39+H42-H43 -> 0 | I44: =I39+I42-I43 -> 0 | ... AW44: =AW39+AW42-AW43 -> 0
...

Sheet Dashboard Análise
A27: Churn (12 Meses) | B27: CAC Último Mês | C27: LTV Último Mês | D27: LTV/CAC Último Mês | E27: Ticket Médio Último Mês | F27: Recorrente Por Cliente Último Mês
A28: =VLOOKUP(A27,A100:B103,2,) -> #N/A | B28: =VLOOKUP(B27,E100:F103,2,) -> #N/A | C28: =VLOOKUP(C27,C100:D103,2,) -> #N/A | D28: =VLOOKUP(D27,G100:H103,2,) -> 0 | E28: =VLOOKUP(E27,I100:J103,2,) -> #N/A | F28: =VLOOKUP(F27,K100:L103,2,) -> #N/A
A100: Churn Último Mês | B100: =HLOOKUP(A109,'DRE '!B4:AW8,5,TRUE) -> #N/A | C100: LTV Último Mês | D100: =HLOOKUP(A109,'Base de dados'!A1:AW54,40,TRUE) -> #N/A | E100: CAC Último Mês | F100: =HLOOKUP(A109,'Base de dados'!A1:AW54,39,TRUE) -> #N/A | G100: LTV/CAC Último Mês | H100: =IFERROR(D100/F100,0) -> 0 | I100: Ticket Médio Último Mês | J100: =HLOOKUP(A109,'Base de dados'!A1:AW54,42,TRUE) -> #N/A | K100: Recorrente Por Cliente Último Mês | L100: =HLOOKUP(A109,'Base de dados'!A1:AW55,55,TRUE) -> #N/A
A101: Churn (3 Meses) | B101: =HLOOKUP(A109,'Base de dados'!A1:AW54,49,TRUE) -> #N/A | C101: LTV (3 Meses) | D101: =HLOOKUP(A109,'Base de dados'!A1:AW54,46,TRUE) -> #N/A | E101: CAC (3 Meses) | F101: =HLOOKUP(A109,'Base de dados'!A1:AW54,45,TRUE) -> #N/A | G101: LTV/CAC (3 Meses) | H101: =IFERROR(D101/F101,0) -> 0 | I101: Ticket Médio (3 Meses) | J101: =HLOOKUP(A109,'Base de dados'!A1:AW54,52,TRUE) -> #N/A | K101: Recorrente Por Cliente (3 Meses) | L101: =HLOOKUP(A109,'Base de dados'!A1:AW56,56,TRUE) -> #N/A
A102: Churn (6 Meses) | B102: =HLOOKUP(A109,'Base de dados'!A1:AW54,50,TRUE) -> #N/A | C102: LTV (6 Meses) | D102: =HLOOKUP(A109,'Base de dados'!A1:AW54,44,TRUE) -> #N/A | E102: CAC (6 Meses) | F102: =HLOOKUP(A109,'Base de dados'!A1:AW54,43,TRUE) -> #N/A | G102: LTV/CAC (6 Meses) | H102: =IFERROR(D102/F102,0) -> 0 | I102: Ticket Médio (6 Meses) | J102: =HLOOKUP(A109,'Base de dados'!A1:AW54,53,TRUE) -> #N/A | K102: Recorrente Por Cliente (6 Meses) | L102: =HLOOKUP(A109,'Base de dados'!A1:AW57,57,TRUE) -> #N/A
A103: Churn (12 Meses) | B103: =HLOOKUP(A109,'Base de dados'!A1:AW54,51,TRUE) -> #N/A | C103: LTV (12 Meses) | D103: =HLOOKUP(A109,'Base de dados'!A1:AW54,48,TRUE) -> #N/A | E103: CAC (12 Meses) | F103: =HLOOKUP(A109,'Base de dados'!A1:AW54,47,TRUE) -> #N/A | G103: LTV/CAC (12 Meses) | H103: =IFERROR(D103/F103,0) -> 0 | I103: Ticket Médio (12 Meses) | J103: =HLOOKUP(A109,'Base de dados'!A1:AW54,54,TRUE) -> #N/A | K103: Recorrente Por Cliente (12 Meses) | L103: =HLOOKUP(A109,'Base de dados'!A1:AW58,58,TRUE) -> #N/A
A109: {='DRE '!I1:J2} -> 0 | B109: 0
A110: 0 | B110: 0

Sheet Base de dados
B1: 43466 | C1: 43497 | D1: 43525 | E1: 43556 | F1: 43586 | G1: 43617 | H1: 43647 | I1: 43678 | J1: 43709 | K1: 43739 | L1: 43770 | M1: 43800 | N1: 43831 | O1: 43862 | P1: 43891 | Q1: 43922 | R1: 43952 | S1: 43983 | T1: 44013 | U1: 44044 | V1: 44075 | W1: 44105 | X1: 44136 | Y1: 44166 | Z1: 44197 | AA1: 44228 | AB1: 44256 | AC1: 44287 | AD1: 44317 | AE1: 44348 | AF1: 44378 | AG1: 44409 | AH1: 44440 | AI1: 44470 | AJ1: 44501 | AK1: 44531 | AL1: 44562 | AM1: 44593 | AN1: 44621 | AO1: 44652 | AP1: 44682 | AQ1: 44713 | AR1: 44743 | AS1: 44774 | AT1: 44805 | AU1: 44835 | AV1: 44866 | AW1: 44896
A2: Fatores | B2: jan-19 | C2: fev-19 | D2: mar-19 | E2: abr-19 | F2: mai-19 | G2: jun-19 | H2: jul-19 | I2: ago-19 | J2: set-19 | K2: out-19 | L2: nov-19 | M2: dez-19 | N2: jan-20 | O2: fev-20 | P2: mar-20 | Q2: abr-20 | R2: mai-20 | S2: jun-20 | T2: jul-20 | U2: ago-20 | V2: set-20 | W2: out-20 | X2: nov-20 | Y2: dez-20 | Z2: jan-21 | AA2: fev-21 | AB2: mar-21 | AC2: abr-21 | AD2: mai-21 | AE2: jun-21 | AF2: jul-21 | AG2: ago-21 | AH2: set-21 | AI2: out-21 | AJ2: nov-21 | AK2: dez-21 | AL2: jan-22 | AM2: fev-22 | AN2: mar-22 | AO2: abr-22 | AP2: mai-22 | AQ2: jun-22 | AR2: jul-22 | AS2: ago-22 | AT2: set-22 | AU2: out-22 | AV2: nov-22 | AW2: dez-22
A3: Total de Clientes | B3: ='DRE '!B5 -> 0 | C3: ='DRE '!C5 -> 0 | D3: ='DRE '!D5 -> 0 | E3: ='DRE '!E5 -> 0 | F3: ='DRE '!F5 -> 0 | G3: ='DRE '!G5 -> 0 | H3: ='DRE '!H5 -> 0 | I3: ='DRE '!I5 -> 0 | ... AW3: ='DRE '!AW5 -> 0
A4: Clientes perdidos | B4: ='DRE '!B7 -> 0 | C4: ='DRE '!C7 -> 0 | D4: ='DRE '!D7 -> 0 | E4: ='DRE '!E7 -> 0 | F4: ='DRE '!F7 -> 0 | G4: ='DRE '!G7 -> 0 | H4: ='DRE '!H7 -> 0 | I4: ='DRE '!I7 -> 0 | ... AW4: ='DRE '!AW7 -> 0
A5: Novos clientes | B5: ='DRE '!B6 -> 0 | C5: ='DRE '!C6 -> 0 | D5: ='DRE '!D6 -> 0 | E5: ='DRE '!E6 -> 0 | F5: ='DRE '!F6 -> 0 | G5: ='DRE '!G6 -> 0 | H5: ='DRE '!H6 -> 0 | I5: ='DRE '!I6 -> 0 | ... AW5: ='DRE '!AW6 -> 0
A6: Churn | B6: ='DRE '!B8 -> 0 | C6: ='DRE '!C8 -> 0 | D6: ='DRE '!D8 -> 0 | E6: ='DRE '!E8 -> 0 | F6: ='DRE '!F8 -> 0 | G6: ='DRE '!G8 -> 0 | H6: ='DRE '!H8 -> 0 | I6: ='DRE '!I8 -> 0 | ... AW6: ='DRE '!AW8 -> 0
A7: Receita Recorrente | B7: ='DRE '!B10 -> 0 | C7: ='DRE '!C10 -> 0 | D7: ='DRE '!D10 -> 0 | E7: ='DRE '!E10 -> 0 | F7: ='DRE '!F10 -> 0 | G7: ='DRE '!G10 -> 0 | H7: ='DRE '!H10 -> 0 | I7: ='DRE '!I10 -> 0 | ... AW7: ='DRE '!AW10 -> 0
A8: Receita Não Recorrente | B8: ='DRE '!B11 -> 0 | C8: ='DRE '!C11 -> 0 | D8: ='DRE '!D11 -> 0 | E8: ='DRE '!E11 -> 0 | F8: ='DRE '!F11 -> 0 | G8: ='DRE '!G11 -> 0 | H8: ='DRE '!H11 -> 0 | I8: ='DRE '!I11 -> 0 | ... AW8: ='DRE '!AW11 -> 0
A9: Receita Bruta | B9: ='DRE '!B12 -> 0 | C9: ='DRE '!C12 -> 0 | D9: ='DRE '!D12 -> 0 | E9: ='DRE '!E12 -> 0 | F9: ='DRE '!F12 -> 0 | G9: ='DRE '!G12 -> 0 | H9: ='DRE '!H12 -> 0 | I9: ='DRE '!I12 -> 0 | ... AW9: ='DRE '!AW12 -> 0
A10: Taxa de Crescimento | B10: ='DRE '!B13 -> 0 | C10: ='DRE '!C13 -> 0 | D10: ='DRE '!D13 -> 0 | E10: ='DRE '!E13 -> 0 | F10: ='DRE '!F13 -> 0 | G10: ='DRE '!G13 -> 0 | H10: ='DRE '!H13 -> 0 | I10: ='DRE '!I13 -> 0 | ... AW10: ='DRE '!AW13 -> 0
A11: (-) Impostos | B11: ='DRE '!B15 -> 0 | C11: ='DRE '!C15 -> 0 | D11: ='DRE '!D15 -> 0 | E11: ='DRE '!E15 -> 0 | F11: ='DRE '!F15 -> 0 | G11: ='DRE '!G15 -> 0 | H11: ='DRE '!H15 -> 0 | I11: ='DRE '!I15 -> 0 | ... AW11: ='DRE '!AW15 -> 0
A12: (-) Deduções | B12: ='DRE '!B16 -> 0 | C12: ='DRE '!C16 -> 0 | D12: ='DRE '!D16 -> 0 | E12: ='DRE '!E16 -> 0 | F12: ='DRE '!F16 -> 0 | G12: ='DRE '!G16 -> 0 | H12: ='DRE '!H16 -> 0 | I12: ='DRE '!I16 -> 0 | ... AW12: ='DRE '!AW16 -> 0
A13: Receita Liquida | B13: ='DRE '!B17 -> 0 | C13: ='DRE '!C17 -> 0 | D13: ='DRE '!D17 -> 0 | E13: ='DRE '!E17 -> 0 | F13: ='DRE '!F17 -> 0 | G13: ='DRE '!G17 -> 0 | H13: ='DRE '!H17 -> 0 | I13: ='DRE '!I17 -> 0 | ... AW13: ='DRE '!AW17 -> 0
A14: (-) Custo do serviço prestado | B14: ='DRE '!B18 -> 0 | C14: ='DRE '!C18 -> 0 | D14: ='DRE '!D18 -> 0 | E14: ='DRE '!E18 -> 0 | F14: ='DRE '!F18 -> 0 | G14: ='DRE '!G18 -> 0 | H14: ='DRE '!H18 -> 0 | I14: ='DRE '!I18 -> 0 | ... AW14: ='DRE '!AW18 -> 0
A15: Lucro Bruto | B15: ='DRE '!B19 -> 0 | C15: ='DRE '!C19 -> 0 | D15: ='DRE '!D19 -> 0 | E15: ='DRE '!E19 -> 0 | F15: ='DRE '!F19 -> 0 | G15: ='DRE '!G19 -> 0 | H15: ='DRE '!H19 -> 0 | I15: ='DRE '!I19 -> 0 | ... AW15: ='DRE '!AW19 -> 0
A16: Margem Bruta | B16: ='DRE '!B20 -> 0 | C16: ='DRE '!C20 -> 0 | D16: ='DRE '!D20 -> 0 | E16: ='DRE '!E20 -> 0 | F16: ='DRE '!F20 -> 0 | G16: ='DRE '!G20 -> 0 | H16: ='DRE '!H20 -> 0 | I16: ='DRE '!I20 -> 0 | ... AW16: ='DRE '!AW20 -> 0
A17: Despesas e custos | B17: ='DRE '!B22 -> 0 | C17: ='DRE '!C22 -> 0 | D17: ='DRE '!D22 -> 0 | E17: ='DRE '!E22 -> 0 | F17: ='DRE '!F22 -> 0 | G17: ='DRE '!G22 -> 0 | H17: ='DRE '!H22 -> 0 | I17: ='DRE '!I22 -> 0 | ... AW17: ='DRE '!AW22 -> 0
A18: Custos com TI | B18: ='DRE '!B23 -> 0 | C18: ='DRE '!C23 -> 0 | D18: ='DRE '!D23 -> 0 | E18: ='DRE '!E23 -> 0 | F18: ='DRE '!F23 -> 0 | G18: ='DRE '!G23 -> 0 | H18: ='DRE '!H23 -> 0 | I18: ='DRE '!I23 -> 0 | ... AW18: ='DRE '!AW23 -> 0
A19: Head count (TI) | B19: ='DRE '!B24 -> 0 | C19: ='DRE '!C24 -> 0 | D19: ='DRE '!D24 -> 0 | E19: ='DRE '!E24 -> 0 | F19: ='DRE '!F24 -> 0 | G19: ='DRE '!G24 -> 0 | H19: ='DRE '!H24 -> 0 | I19: ='DRE '!I24 -> 0 | ... AW19: ='DRE '!AW24 -> 0
A20: Pessoal | B20: ='DRE '!B25 -> 0 | C20: ='DRE '!C25 -> 0 | D20: ='DRE '!D25 -> 0 | E20: ='DRE '!E25 -> 0 | F20: ='DRE '!F25 -> 0 | G20: ='DRE '!G25 -> 0 | H20: ='DRE '!H25 -> 0 | I20: ='DRE '!I25 -> 0 | ... AW20: ='DRE '!AW25 -> 0
A21: Softwares | B21: ='DRE '!B26 -> 0 | C21: ='DRE '!C26 -> 0 | D21: ='DRE '!D26 -> 0 | E21: ='DRE '!E26 -> 0 | F21: ='DRE '!F26 -> 0 | G21: ='DRE '!G26 -> 0 | H21: ='DRE '!H26 -> 0 | I21: ='DRE '!I26 -> 0 | ... AW21: ='DRE '!AW26 -> 0
A22: Outros | B22: ='DRE '!B27 -> 0 | C22: ='DRE '!C27 -> 0 | D22: ='DRE '!D27 -> 0 | E22: ='DRE '!E27 -> 0 | F22: ='DRE '!F27 -> 0 | G22: ='DRE '!G27 -> 0 | H22: ='DRE '!H27 -> 0 | I22: ='DRE '!I27 -> 0 | ... AW22: ='DRE '!AW27 -> 0
A23: Custos Administrativos | B23: ='DRE '!B28 -> 0 | C23: ='DRE '!C28 -> 0 | D23: ='DRE '!D28 -> 0 | E23: ='DRE '!E28 -> 0 | F23: ='DRE '!F28 -> 0 | G23: ='DRE '!G28 -> 0 | H23: ='DRE '!H28 -> 0 | I23: ='DRE '!I28 -> 0 | ... AW23: ='DRE '!AW28 -> 0
A24: Head count (ADM) | B24: ='DRE '!B29 -> 0 | C24: ='DRE '!C29 -> 0 | D24: ='DRE '!D29 -> 0 | E24: ='DRE '!E29 -> 0 | F24: ='DRE '!F29 -> 0 | G24: ='DRE '!G29 -> 0 | H24: ='DRE '!H29 -> 0 | I24: ='DRE '!I29 -> 0 | ... AW24: ='DRE '!AW29 -> 0
A25: Pessoal | B25: ='DRE '!B30 -> 0 | C25: ='DRE '!C30 -> 0 | D25: ='DRE '!D30 -> 0 | E25: ='DRE '!E30 -> 0 | F25: ='DRE '!F30 -> 0 | G25: ='DRE '!G30 -> 0 | H25: ='DRE '!H30 -> 0 | I25: ='DRE '!I30 -> 0 | ... AW25: ='DRE '!AW30 -> 0
A26: Softwares | B26: ='DRE '!B31 -> 0 | C26: ='DRE '!C31 -> 0 | D26: ='DRE '!D31 -> 0 | E26: ='DRE '!E31 -> 0 | F26: ='DRE '!F31 -> 0 | G26: ='DRE '!G31 -> 0 | H26: ='DRE '!H31 -> 0 | I26: ='DRE '!I31 -> 0 | ... AW26: ='DRE '!AW31 -> 0
A27: Outros | B27: ='DRE '!B32 -> 0 | C27: ='DRE '!C32 -> 0 | D27: ='DRE '!D32 -> 0 | E27: ='DRE '!E32 -> 0 | F27: ='DRE '!F32 -> 0 | G27: ='DRE '!G32 -> 0 | H27: ='DRE '!H32 -> 0 | I27: ='DRE '!I32 -> 0 | ... AW27: ='DRE '!AW32 -> 0
A28: Comercial/Marketing | B28: ='DRE '!B33 -> 0 | C28: ='DRE '!C33 -> 0 | D28: ='DRE '!D33 -> 0 | E28: ='DRE '!E33 -> 0 | F28: ='DRE '!F33 -> 0 | G28: ='DRE '!G33 -> 0 | H28: ='DRE '!H33 -> 0 | I28: ='DRE '!I33 -> 0 | ... AW28: ='DRE '!AW33 -> 0
... A35: Margem EBIT | B35: ='DRE '!B40 -> 0 | C35: ='DRE '!C40 -> 0 | D35: ='DRE '!D40 -> 0 | E35: ='DRE '!E40 -> 0 | F35: ='DRE '!F40 -> 0 | G35: ='DRE '!G40 -> 0 | H35: ='DRE '!H40 -> 0 | I35: ='DRE '!I40 -> 0 | ... AW35: ='DRE '!AW40 -> 0
A36: Resultado Financeiro (+/-) | B36: ='DRE '!B42 -> 0 | C36: ='DRE '!C42 -> 0 | D36: ='DRE '!D42 -> 0 | E36: ='DRE '!E42 -> 0 | F36: ='DRE '!F42 -> 0 | G36: ='DRE '!G42 -> 0 | H36: ='DRE '!H42 -> 0 | I36: ='DRE '!I42 -> 0 | ... AW36: ='DRE '!AW42 -> 0
A37: Imposto Sobre O Lucro | B37: ='DRE '!B43 -> 0 | C37: ='DRE '!C43 -> 0 | D37: ='DRE '!D43 -> 0 | E37: ='DRE '!E43 -> 0 | F37: ='DRE '!F43 -> 0 | G37: ='DRE '!G43 -> 0 | H37: ='DRE '!H43 -> 0 | I37: ='DRE '!I43 -> 0 | ... AW37: ='DRE '!AW43 -> 0
A38: Lucro Líquido | B38: ='DRE '!B44 -> 0 | C38: ='DRE '!C44 -> 0 | D38: ='DRE '!D44 -> 0 | E38: ='DRE '!E44 -> 0 | F38: ='DRE '!F44 -> 0 | G38: ='DRE '!G44 -> 0 | H38: ='DRE '!H44 -> 0 | I38: ='DRE '!I44 -> 0 | ... AW38: ='DRE '!AW44 -> 0
A39: CAC Mensal | B39: =IF(B5=0,0,B28/B5) -> 0 | C39: =IF(C5=0,0,C28/C5) -> 0 | D39: =IF(D5=0,0,D28/D5) -> 0 | E39: =IF(E5=0,0,E28/E5) -> 0 | F39: =IF(F5=0,0,F28/F5) -> 0 | G39: =IF(G5=0,0,G28/G5) -> 0 | H39: =IF(H5=0,0,H28/H5) -> 0 | I39: =IF(I5=0,0,I28/I5) -> 0 | ... AW39: =IF(AW5=0,0,AW28/AW5) -> 0
A40: LTV Mensal | B40: =IF(B6=0,0,B42/B6) -> 0 | C40: =IF(C6=0,0,C42/C6) -> 0 | D40: =IF(D6=0,0,D42/D6) -> 0 | E40: =IF(E6=0,0,E42/E6) -> 0 | F40: =IF(F6=0,0,F42/F6) -> 0 | G40: =IF(G6=0,0,G42/G6) -> 0 | H40: =IF(H6=0,0,H42/H6) -> 0 | I40: =IF(I6=0,0,I42/I6) -> 0 | ... AW40: =IF(AW6=0,0,AW42/AW6) -> 0
A41: LTV/CAC Mensal | B41: =IF(B39=0,0,B40/B39) -> 0 | C41: =IF(C39=0,0,C40/C39) -> 0 | D41: =IF(D39=0,0,D40/D39) -> 0 | E41: =IF(E39=0,0,E40/E39) -> 0 | F41: =IF(F39=0,0,F40/F39) -> 0 | G41: =IF(G39=0,0,G40/G39) -> 0 | H41: =IF(H39=0,0,H40/H39) -> 0 | I41: =IF(I39=0,0,I40/I39) -> 0 | ... AW41: =IF(AW39=0,0,AW40/AW39) -> 0
A42: TICKET MÉDIO | B42: =IF(B3=0,0,B9/B3) -> 0 | C42: =IF(C3=0,0,C9/C3) -> 0 | D42: =IF(D3=0,0,D9/D3) -> 0 | E42: =IF(E3=0,0,E9/E3) -> 0 | F42: =IF(F3=0,0,F9/F3) -> 0 | G42: =IF(G3=0,0,G9/G3) -> 0 | H42: =IF(H3=0,0,H9/H3) -> 0 | I42: =IF(I3=0,0,I9/I3) -> 0 | ... AW42: =IF(AW3=0,0,AW9/AW3) -> 0
A43: CAC (6 Meses) | B43: =IF(B5=0,0,B28/B5) -> 0 | C43: =IF(SUM(B5,C5)=0,0,SUM(B28,C28)/SUM(B5,C5)) -> 0 | D43: =IF(SUM(B5,C5,D5)=0,0,SUM(B28,C28,D28)/SUM(B5,C5,D5)) -> 0 | E43: =IF(SUM(B5,C5,D5,E5)=0,0,SUM(B28,C28,D28,E28)/SUM(B5,C5,D5,E5)) -> 0 | F43: =IF(SUM(B5:F5)=0,0,SUM(B28:F28)/SUM(B5:F5)) -> 0 | G43: =IF(SUM(B5:G5)=0,0,SUM(B28:G28)/SUM(B5:G5)) -> 0 | H43: =IF(SUM(C5:H5)=0,0,SUM(C28:H28)/SUM(C5:H5)) -> 0 | I43: =IF(SUM(D5:I5)=0,0,SUM(D28:I28)/SUM(D5:I5)) -> 0 | J43: =IF(SUM(E5:J5)=0,0,SUM(E28:J28)/SUM(E5:J5)) -> 0 | K43: =IF(SUM(F5:K5)=0,0,SUM(F28:K28)/SUM(F5:K5)) -> 0 | L43: =IF(SUM(G5:L5)=0,0,SUM(G28:L28)/SUM(G5:L5)) -> 0 | M43: =IF(SUM(H5:M5)=0,0,SUM(H28:M28)/SUM(H5:M5)) -> 0 | N43: =IF(SUM(I5:N5)=0,0,SUM(I28:N28)/SUM(I5:N5)) -> 0 | ... AW43: =IF(SUM(AR5:AW5)=0,0,SUM(AR28:AW28)/SUM(AR5:AW5)) -> 0
A44: LTV (6 Meses) | B44: =IF(B50=0,0,B53/B50) -> 0 | C44: =IF(C50=0,0,C53/C50) -> 0 | D44: =IF(D50=0,0,D53/D50) -> 0 | E44: =IF(E50=0,0,E53/E50) -> 0 | F44: =IF(F50=0,0,F53/F50) -> 0 | G44: =IF(G50=0,0,G53/G50) -> 0 | H44: =IF(H50=0,0,H53/H50) -> 0 | I44: =IF(I50=0,0,I53/I50) -> 0 | ... AW44: =IF(AW50=0,0,AW53/AW50) -> 0
A45: CAC (3 Meses) | B45: =IF(B5=0,0,B28/B5) -> 0 | C45: =IF(SUM(B5,C5)=0,0,SUM(B28,C28)/SUM(B5,C5)) -> 0 | D45: =IF(SUM(B5:D5)=0,0,SUM(B28:D28)/SUM(B5:D5)) -> 0 | E45: =IF(SUM(C5:E5)=0,0,SUM(C28:E28)/SUM(C5:E5)) -> 0 | F45: =IF(SUM(D5:F5)=0,0,SUM(D28:F28)/SUM(D5:F5)) -> 0 | G45: =IF(SUM(E5:G5)=0,0,SUM(E28:G28)/SUM(E5:G5)) -> 0 | H45: =IF(SUM(F5:H5)=0,0,SUM(F28:H28)/SUM(F5:H5)) -> 0 | I45: =IF(SUM(G5:I5)=0,0,SUM(G28:I28)/SUM(G5:I5)) -> 0 | J45: =IF(SUM(H5:J5)=0,0,SUM(H28:J28)/SUM(H5:J5)) -> 0 | K45: =IF(SUM(I5:K5)=0,0,SUM(I28:K28)/SUM(I5:K5)) -> 0 | ... AW45: =IF(SUM(AU5:AW5)=0,0,SUM(AU28:AW28)/SUM(AU5:AW5)) -> 0
A46: LTV (3 Meses) | B46: =IF(B49=0,0,B52/B49) -> 0 | C46: =IF(C49=0,0,C52/C49) -> 0 | D46: =IF(D49=0,0,D52/D49) -> 0 | E46: =IF(E49=0,0,E52/E49) -> 0 | F46: =IF(F49=0,0,F52/F49) -> 0 | G46: =IF(G49=0,0,G52/G49) -> 0 | H46: =IF(H49=0,0,H52/H49) -> 0 | I46: =IF(I49=0,0,I52/I49) -> 0 | ... AW46: =IF(AW49=0,0,AW52/AW49) -> 0
...
